<?xml version="1.0" encoding="utf-8"?>
<!-- =================================================================================== -->
<!-- |    This document was autogenerated by xacro from cleaner.xacro                  | -->
<!-- |    EDITING THIS FILE BY HAND IS NOT RECOMMENDED                                 | -->
<!-- =================================================================================== -->
<robot name="SweepBOT">
  <!-- overwatch camara -->
  <!-- Hokuyo Laser - TOP -->
  <!-- Hokuyo Laser - FRONT -->
  <!-- Hokuyo Laser - LEFT -->
  <!-- Hokuyo Laser - RIGHT -->
  <!-- Hokuyo Laser - REAR -->
  <!-- <xacro:include filename="$(find hector_sensors_description)/urdf/hokuyo_utm30lx.urdf.xacro"/> -->
  <link name="chasis_footprint"/>
  <joint name="chasis_footprint_joint" type="fixed">
    <parent link="chasis_footprint"/>
    <child link="chasis"/>
    <origin rpy="0.0 0.0 0.0" xyz="0.0 0.0 0.0"/>
  </joint>
  <link name="chasis">
    <inertial>
      <origin rpy="0.0 1.57 0.0" xyz="0.0 0.0 0.0"/>
      <mass value="15.0"/>
      <inertia ixx="1.503125" ixy="0.0" ixz="0.0" iyy="1.5625" iyz="0.0" izz="0.565625"/>
    </inertial>
    <visual name="">
      <origin rpy="0.0 0.0 0.0" xyz="0.0 0.0 0.0"/>
      <geometry>
        <box size="1.0 0.45 0.5"/>
      </geometry>
      <material name="">
        <color rgba="0.0 1.0 0.0 1.0"/>
      </material>
    </visual>
    <collision>
      <origin rpy="0.0 0.0 0.0" xyz="0.0 0.0 0.0"/>
      <geometry>
        <box size="1.0 0.45 0.5"/>
      </geometry>
    </collision>
  </link>
  <gazebo reference="chasis">
    <material>Gazebo/Orange</material>
  </gazebo>
  <link name="wheel_left_fore">
    <inertial>
      <mass value="2.0"/>
      <inertia ixx="1.503125" ixy="0.0" ixz="0.0" iyy="0.0" iyz="0.0" izz="0.565625"/>
    </inertial>
    <visual name="">
      <origin rpy="1.57075 0 0" xyz="0 0 0"/>
      <geometry>
        <cylinder length="0.1" radius="0.1"/>
      </geometry>
      <material name="">
        <color rgba="1.0 0.0 0.0 1.0"/>
        <texture filename=""/>
      </material>
    </visual>
    <collision>
      <origin rpy="1.57075 0 0" xyz="0 0 0"/>
      <geometry>
        <cylinder length="0.1" radius="0.1"/>
      </geometry>
    </collision>
  </link>
  <gazebo reference="&quot;wheel_left_fore">
    <material>Gazebo/Red</material>
  </gazebo>
  <joint name="body_wheel_left_fore_joint" type="continuous">
    <parent link="chasis"/>
    <child link="wheel_left_fore"/>
    <limit effort="0.0" lower="0.0" upper="0.0" velocity="0.0"/>
    <!-- <origin rpy="0 0 0" xyz="-0.133333333333 0 -0.085"/> -->
    <origin rpy="0.0 0.0 0.0" xyz="0.3 0.2 -0.25"/>
    <axis xyz="0.0 1.0 0.0"/>
  </joint>
  <link name="wheel_right_fore">
    <inertial>
      <mass value="2.0"/>
      <inertia ixx="1.503125" ixy="0.0" ixz="0.0" iyy="0.0" iyz="0.0" izz="0.565625"/>
    </inertial>
    <visual name="">
      <origin rpy="1.57075 0 0" xyz="0 0 0"/>
      <geometry>
        <cylinder length="0.1" radius="0.1"/>
      </geometry>
      <material name="">
        <color rgba="1.0 0.0 0.0 1.0"/>
        <texture filename=""/>
      </material>
    </visual>
    <collision>
      <origin rpy="1.57075 0 0" xyz="0 0 0"/>
      <geometry>
        <cylinder length="0.1" radius="0.1"/>
      </geometry>
    </collision>
  </link>
  <gazebo reference="&quot;wheel_right_fore">
    <material>Gazebo/Red</material>
  </gazebo>
  <joint name="body_wheel_right_fore_joint" type="continuous">
    <parent link="chasis"/>
    <child link="wheel_right_fore"/>
    <limit effort="0.0" lower="0.0" upper="0.0" velocity="0.0"/>
    <!-- <origin rpy="0 0 0" xyz="-0.133333333333 0 -0.085"/> -->
    <origin rpy="0.0 0.0 0.0" xyz="0.3 -0.2 -0.25"/>
    <axis xyz="0.0 1.0 0.0"/>
  </joint>
  <link name="wheel_left_aft">
    <inertial>
      <mass value="2.0"/>
      <inertia ixx="1.503125" ixy="0.0" ixz="0.0" iyy="0.0" iyz="0.0" izz="0.565625"/>
    </inertial>
    <visual name="">
      <origin rpy="1.57075 0 0" xyz="0 0 0"/>
      <geometry>
        <cylinder length="0.1" radius="0.1"/>
      </geometry>
      <material name="">
        <color rgba="1.0 0.0 0.0 1.0"/>
        <texture filename=""/>
      </material>
    </visual>
    <collision>
      <origin rpy="1.57075 0 0" xyz="0 0 0"/>
      <geometry>
        <cylinder length="0.1" radius="0.1"/>
      </geometry>
    </collision>
  </link>
  <gazebo reference="&quot;wheel_left_aft">
    <material>Gazebo/Red</material>
  </gazebo>
  <joint name="body_wheel_left_aft_joint" type="continuous">
    <parent link="chasis"/>
    <child link="wheel_left_aft"/>
    <limit effort="0.0" lower="0.0" upper="0.0" velocity="0.0"/>
    <!-- <origin rpy="0 0 0" xyz="-0.133333333333 0 -0.085"/> -->
    <origin rpy="0.0 0.0 0.0" xyz="-0.3 0.2 -0.25"/>
    <axis xyz="0.0 1.0 0.0"/>
  </joint>
  <link name="wheel_right_aft">
    <inertial>
      <mass value="2.0"/>
      <inertia ixx="1.503125" ixy="0.0" ixz="0.0" iyy="0.0" iyz="0.0" izz="0.565625"/>
    </inertial>
    <visual name="">
      <origin rpy="1.57075 0 0" xyz="0 0 0"/>
      <geometry>
        <cylinder length="0.1" radius="0.1"/>
      </geometry>
      <material name="">
        <color rgba="1.0 0.0 0.0 1.0"/>
        <texture filename=""/>
      </material>
    </visual>
    <collision>
      <origin rpy="1.57075 0 0" xyz="0 0 0"/>
      <geometry>
        <cylinder length="0.1" radius="0.1"/>
      </geometry>
    </collision>
  </link>
  <gazebo reference="&quot;wheel_right_aft">
    <material>Gazebo/Red</material>
  </gazebo>
  <joint name="body_wheel_right_aft_joint" type="continuous">
    <parent link="chasis"/>
    <child link="wheel_right_aft"/>
    <limit effort="0.0" lower="0.0" upper="0.0" velocity="0.0"/>
    <!-- <origin rpy="0 0 0" xyz="-0.133333333333 0 -0.085"/> -->
    <origin rpy="0.0 0.0 0.0" xyz="-0.3 -0.2 -0.25"/>
    <axis xyz="0.0 1.0 0.0"/>
  </joint>
  <!-- HOKUYO as RPLIDAR -->
  <!-- <xacro:hokuyo_utm30lx name="hokuyo_laser" parent="chasis" ros_topic="hokuyo_scan" update_rate="40" ray_count="1040" min_angle="130" max_angle="-130">
    <origin xyz="0 0 0.3" rpy="0 0 0" />
  </xacro:hokuyo_utm30lx> -->
  <gazebo reference="left_camera_frame">
    <sensor name="stereo_camera" type="multicamera">
      <update_rate>30.0</update_rate>
      <camera name="left_camera">
        <horizontal_fov>1.3962634</horizontal_fov>
        <image>
          <width>800</width>
          <height>800</height>
          <format>R8G8B8</format>
        </image>
        <clip>
          <near>0.02</near>
          <far>300</far>
        </clip>
        <noise>
          <type>gaussian</type>
          <mean>0.0</mean>
          <stddev>0.007</stddev>
        </noise>
      </camera>
      <camera name="right_camera">
        <pose>0 -0.07 0 0 0 0</pose>
        <horizontal_fov>1.3962634</horizontal_fov>
        <image>
          <width>800</width>
          <height>800</height>
          <format>R8G8B8</format>
        </image>
        <clip>
          <near>0.02</near>
          <far>300</far>
        </clip>
        <noise>
          <type>gaussian</type>
          <mean>0.0</mean>
          <stddev>0.007</stddev>
        </noise>
      </camera>
      <plugin filename="libgazebo_ros_multicamera.so" name="stereo_camera_controller">
        <alwaysOn>true</alwaysOn>
        <updateRate>0.0</updateRate>
        <cameraName>multisense_sl/camera</cameraName>
        <imageTopicName>image_raw</imageTopicName>
        <cameraInfoTopicName>camera_info</cameraInfoTopicName>
        <frameName>left_camera_optical_frame</frameName>
        <!--<rightFrameName>right_camera_optical_frame</rightFrameName>-->
        <hackBaseline>0.07</hackBaseline>
        <distortionK1>0.0</distortionK1>
        <distortionK2>0.0</distortionK2>
        <distortionK3>0.0</distortionK3>
        <distortionT1>0.0</distortionT1>
        <distortionT2>0.0</distortionT2>
      </plugin>
    </sensor>
  </gazebo>
  <!-- CAMERA LEFT -->
  <link name="left_camera">
    <inertial>
      <origin rpy="0.0 0.0 0.0" xyz="0.0 0.0 0.0"/>
      <mass value="0.0"/>
      <inertia ixx="0.0" ixy="0.0" ixz="0.0" iyy="0.0" iyz="0.0" izz="0.0"/>
    </inertial>
    <visual name="">
      <origin rpy="0.0 0.0 0.0" xyz="0.0 0.0 0.0"/>
      <geometry>
        <box size="0.1 0.1 0.1"/>
      </geometry>
      <material name="">
        <color rgba="0.0 0.0 1.0 1.0"/>
        <texture filename=""/>
      </material>
    </visual>
    <collision>
      <origin rpy="0.0 0.0 0.0" xyz="0.0 0.0 0.0"/>
      <geometry>
        <box size="0.0 0.0 0.0"/>
      </geometry>
    </collision>
  </link>
  <joint name="left_camera_joint" type="fixed">
    <origin rpy="0.0 0.0 0.0" xyz="0.45 -0.274725274725 0.0"/>
    <parent link="chasis"/>
    <child link="left_camera"/>
    <!-- <axis xyz="0.0 0.0 0.0"/> -->
    <!-- <limit lower="0.0" upper="0.0" effort="0.0" velocity="0.0"/> -->
  </joint>
  <!-- CAMERA RIGHT -->
  <link name="right_camera">
    <inertial>
      <origin rpy="0.0 0.0 0.0" xyz="0.0 0.0 0.0"/>
      <mass value="0.0"/>
      <inertia ixx="0.0" ixy="0.0" ixz="0.0" iyy="0.0" iyz="0.0" izz="0.0"/>
    </inertial>
    <visual name="">
      <origin rpy="0.0 0.0 0.0" xyz="0.0 0.0 0.0"/>
      <geometry>
        <box size="0.1 0.1 0.1"/>
      </geometry>
      <material name="">
        <color rgba="0.0 0.0 1.0 1.0"/>
        <texture filename=""/>
      </material>
    </visual>
    <collision>
      <origin rpy="0.0 0.0 0.0" xyz="0.0 0.0 0.0"/>
      <geometry>
        <box size="0.0 0.0 0.0"/>
      </geometry>
    </collision>
  </link>
  <joint name="right_camera_joint" type="fixed">
    <origin rpy="0.0 0.0 0.0" xyz="0.45 0.274725274725 0.0"/>
    <parent link="chasis"/>
    <child link="right_camera"/>
    <!-- <axis xyz="0.0 0.0 0.0"/> -->
    <!-- <limit lower="0.0" upper="0.0" effort="0.0" velocity="0.0"/> -->
  </joint>
  <!-- <xacro:overwatch_cam/> -->
  <!-- LASERS -->
  <!-- <xacro:laser_top/> -->
  <!-- <xacro:laser_front/> -->
  <!-- <xacro:laser_left/> -->
  <!-- <xacro:laser_right/> -->
  <!-- <xacro:laser_rear/> -->
  <!-- SKIP STEERING -->
  <gazebo>
    <plugin filename="libgazebo_ros_skid_steer_drive.so" name="skid_steer_drive_controller">
      <updateRate>100.0</updateRate>
      <robotNamespace>/</robotNamespace>
      <leftFrontJoint>body_wheel_left_fore_joint</leftFrontJoint>
      <rightFrontJoint>body_wheel_right_fore_joint</rightFrontJoint>
      <leftRearJoint>body_wheel_left_aft_joint</leftRearJoint>
      <rightRearJoint>body_wheel_right_aft_joint</rightRearJoint>
      <wheelSeparation>0.5</wheelSeparation>
      <wheelDiameter>0.2</wheelDiameter>
      <robotBaseFrame>chasis_footprint</robotBaseFrame>
      <torque>20</torque>
      <topicName>cmd_vel</topicName>
      <broadcastTF>true</broadcastTF>
      <commandTopic> cmd_vel </commandTopic>
      <odometryTopic> odom </odometryTopic>
      <odometryFrame> odom </odometryFrame>
      <covariance_x> 0.000100 </covariance_x>
      <covariance_y> 0.000100 </covariance_y>
      <covariance_yaw> 0.010000 </covariance_yaw>
    </plugin>
  </gazebo>
  <!--  -->
</robot>

